{
 "cells": [
  {
   "cell_type": "code",
   "execution_count": 1,
   "metadata": {},
   "outputs": [
    {
     "name": "stderr",
     "output_type": "stream",
     "text": [
      "/home/vayzenbe/anaconda3/envs/ml_new/lib/python3.9/site-packages/tqdm/auto.py:22: TqdmWarning: IProgress not found. Please update jupyter and ipywidgets. See https://ipywidgets.readthedocs.io/en/stable/user_install.html\n",
      "  from .autonotebook import tqdm as notebook_tqdm\n"
     ]
    }
   ],
   "source": [
    "import sys\n",
    "\n",
    "import os, argparse, shutil\n",
    "from collections import OrderedDict\n",
    "import torch\n",
    "\n",
    "import torch.nn as nn\n",
    "import torchvision\n",
    "from torchvision import transforms\n",
    "from torchvision import datasets\n",
    "import numpy as np\n",
    "\n",
    "import models\n",
    "import pdb\n",
    "import model_funcs\n",
    "import load_stim_folders as load_stim"
   ]
  },
  {
   "cell_type": "code",
   "execution_count": 3,
   "metadata": {},
   "outputs": [],
   "source": [
    "im_dir = '/lab_data/behrmannlab/image_sets/test_ims/train/'\n",
    "transform = transforms.Compose([\n",
    "        transforms.RandomResizedCrop(224),\n",
    "        transforms.RandomHorizontalFlip(),\n",
    "        transforms.ToTensor(),\n",
    "        transforms.Normalize(mean=[0.485, 0.456, 0.406],\n",
    "                                             std=[0.229, 0.224, 0.225])])\n",
    "\n",
    "im_dataset = load_stim.load_stim(im_dir, transform=transform)\n",
    "\n",
    "dataloader = torch.utils.data.DataLoader(im_dataset, batch_size=24, shuffle=False, num_workers = 4, pin_memory=True)"
   ]
  },
  {
   "cell_type": "code",
   "execution_count": 4,
   "metadata": {},
   "outputs": [
    {
     "ename": "IsADirectoryError",
     "evalue": "Caught IsADirectoryError in DataLoader worker process 0.\nOriginal Traceback (most recent call last):\n  File \"/home/vayzenbe/anaconda3/envs/ml_new/lib/python3.9/site-packages/torch/utils/data/_utils/worker.py\", line 302, in _worker_loop\n    data = fetcher.fetch(index)\n  File \"/home/vayzenbe/anaconda3/envs/ml_new/lib/python3.9/site-packages/torch/utils/data/_utils/fetch.py\", line 49, in fetch\n    data = [self.dataset[idx] for idx in possibly_batched_index]\n  File \"/home/vayzenbe/anaconda3/envs/ml_new/lib/python3.9/site-packages/torch/utils/data/_utils/fetch.py\", line 49, in <listcomp>\n    data = [self.dataset[idx] for idx in possibly_batched_index]\n  File \"/user_data/vayzenbe/GitHub_Repos/ginn/modelling/load_stim_folders.py\", line 28, in __getitem__\n    image = Image.open(img_loc).convert(\"RGB\")\n  File \"/home/vayzenbe/anaconda3/envs/ml_new/lib/python3.9/site-packages/PIL/Image.py\", line 3092, in open\n    fp = builtins.open(filename, \"rb\")\nIsADirectoryError: [Errno 21] Is a directory: '/lab_data/behrmannlab/image_sets/test_ims/train'\n",
     "output_type": "error",
     "traceback": [
      "\u001b[0;31m---------------------------------------------------------------------------\u001b[0m",
      "\u001b[0;31mIsADirectoryError\u001b[0m                         Traceback (most recent call last)",
      "\u001b[1;32m/user_data/vayzenbe/GitHub_Repos/ginn/modelling/explore_dnns.ipynb Cell 3\u001b[0m in \u001b[0;36m<cell line: 1>\u001b[0;34m()\u001b[0m\n\u001b[0;32m----> <a href='vscode-notebook-cell://ssh-remote%2Bmind-0-13/user_data/vayzenbe/GitHub_Repos/ginn/modelling/explore_dnns.ipynb#W2sdnNjb2RlLXJlbW90ZQ%3D%3D?line=0'>1</a>\u001b[0m \u001b[39mfor\u001b[39;00m data, ind,file \u001b[39min\u001b[39;00m dataloader:\n\u001b[1;32m      <a href='vscode-notebook-cell://ssh-remote%2Bmind-0-13/user_data/vayzenbe/GitHub_Repos/ginn/modelling/explore_dnns.ipynb#W2sdnNjb2RlLXJlbW90ZQ%3D%3D?line=1'>2</a>\u001b[0m     \u001b[39mprint\u001b[39m(data\u001b[39m.\u001b[39mshape)\n\u001b[1;32m      <a href='vscode-notebook-cell://ssh-remote%2Bmind-0-13/user_data/vayzenbe/GitHub_Repos/ginn/modelling/explore_dnns.ipynb#W2sdnNjb2RlLXJlbW90ZQ%3D%3D?line=2'>3</a>\u001b[0m     \u001b[39mprint\u001b[39m(ind)\n",
      "File \u001b[0;32m~/anaconda3/envs/ml_new/lib/python3.9/site-packages/torch/utils/data/dataloader.py:681\u001b[0m, in \u001b[0;36m_BaseDataLoaderIter.__next__\u001b[0;34m(self)\u001b[0m\n\u001b[1;32m    678\u001b[0m \u001b[39mif\u001b[39;00m \u001b[39mself\u001b[39m\u001b[39m.\u001b[39m_sampler_iter \u001b[39mis\u001b[39;00m \u001b[39mNone\u001b[39;00m:\n\u001b[1;32m    679\u001b[0m     \u001b[39m# TODO(https://github.com/pytorch/pytorch/issues/76750)\u001b[39;00m\n\u001b[1;32m    680\u001b[0m     \u001b[39mself\u001b[39m\u001b[39m.\u001b[39m_reset()  \u001b[39m# type: ignore[call-arg]\u001b[39;00m\n\u001b[0;32m--> 681\u001b[0m data \u001b[39m=\u001b[39m \u001b[39mself\u001b[39;49m\u001b[39m.\u001b[39;49m_next_data()\n\u001b[1;32m    682\u001b[0m \u001b[39mself\u001b[39m\u001b[39m.\u001b[39m_num_yielded \u001b[39m+\u001b[39m\u001b[39m=\u001b[39m \u001b[39m1\u001b[39m\n\u001b[1;32m    683\u001b[0m \u001b[39mif\u001b[39;00m \u001b[39mself\u001b[39m\u001b[39m.\u001b[39m_dataset_kind \u001b[39m==\u001b[39m _DatasetKind\u001b[39m.\u001b[39mIterable \u001b[39mand\u001b[39;00m \\\n\u001b[1;32m    684\u001b[0m         \u001b[39mself\u001b[39m\u001b[39m.\u001b[39m_IterableDataset_len_called \u001b[39mis\u001b[39;00m \u001b[39mnot\u001b[39;00m \u001b[39mNone\u001b[39;00m \u001b[39mand\u001b[39;00m \\\n\u001b[1;32m    685\u001b[0m         \u001b[39mself\u001b[39m\u001b[39m.\u001b[39m_num_yielded \u001b[39m>\u001b[39m \u001b[39mself\u001b[39m\u001b[39m.\u001b[39m_IterableDataset_len_called:\n",
      "File \u001b[0;32m~/anaconda3/envs/ml_new/lib/python3.9/site-packages/torch/utils/data/dataloader.py:1376\u001b[0m, in \u001b[0;36m_MultiProcessingDataLoaderIter._next_data\u001b[0;34m(self)\u001b[0m\n\u001b[1;32m   1374\u001b[0m \u001b[39melse\u001b[39;00m:\n\u001b[1;32m   1375\u001b[0m     \u001b[39mdel\u001b[39;00m \u001b[39mself\u001b[39m\u001b[39m.\u001b[39m_task_info[idx]\n\u001b[0;32m-> 1376\u001b[0m     \u001b[39mreturn\u001b[39;00m \u001b[39mself\u001b[39;49m\u001b[39m.\u001b[39;49m_process_data(data)\n",
      "File \u001b[0;32m~/anaconda3/envs/ml_new/lib/python3.9/site-packages/torch/utils/data/dataloader.py:1402\u001b[0m, in \u001b[0;36m_MultiProcessingDataLoaderIter._process_data\u001b[0;34m(self, data)\u001b[0m\n\u001b[1;32m   1400\u001b[0m \u001b[39mself\u001b[39m\u001b[39m.\u001b[39m_try_put_index()\n\u001b[1;32m   1401\u001b[0m \u001b[39mif\u001b[39;00m \u001b[39misinstance\u001b[39m(data, ExceptionWrapper):\n\u001b[0;32m-> 1402\u001b[0m     data\u001b[39m.\u001b[39;49mreraise()\n\u001b[1;32m   1403\u001b[0m \u001b[39mreturn\u001b[39;00m data\n",
      "File \u001b[0;32m~/anaconda3/envs/ml_new/lib/python3.9/site-packages/torch/_utils.py:461\u001b[0m, in \u001b[0;36mExceptionWrapper.reraise\u001b[0;34m(self)\u001b[0m\n\u001b[1;32m    457\u001b[0m \u001b[39mexcept\u001b[39;00m \u001b[39mTypeError\u001b[39;00m:\n\u001b[1;32m    458\u001b[0m     \u001b[39m# If the exception takes multiple arguments, don't try to\u001b[39;00m\n\u001b[1;32m    459\u001b[0m     \u001b[39m# instantiate since we don't know how to\u001b[39;00m\n\u001b[1;32m    460\u001b[0m     \u001b[39mraise\u001b[39;00m \u001b[39mRuntimeError\u001b[39;00m(msg) \u001b[39mfrom\u001b[39;00m \u001b[39mNone\u001b[39m\n\u001b[0;32m--> 461\u001b[0m \u001b[39mraise\u001b[39;00m exception\n",
      "\u001b[0;31mIsADirectoryError\u001b[0m: Caught IsADirectoryError in DataLoader worker process 0.\nOriginal Traceback (most recent call last):\n  File \"/home/vayzenbe/anaconda3/envs/ml_new/lib/python3.9/site-packages/torch/utils/data/_utils/worker.py\", line 302, in _worker_loop\n    data = fetcher.fetch(index)\n  File \"/home/vayzenbe/anaconda3/envs/ml_new/lib/python3.9/site-packages/torch/utils/data/_utils/fetch.py\", line 49, in fetch\n    data = [self.dataset[idx] for idx in possibly_batched_index]\n  File \"/home/vayzenbe/anaconda3/envs/ml_new/lib/python3.9/site-packages/torch/utils/data/_utils/fetch.py\", line 49, in <listcomp>\n    data = [self.dataset[idx] for idx in possibly_batched_index]\n  File \"/user_data/vayzenbe/GitHub_Repos/ginn/modelling/load_stim_folders.py\", line 28, in __getitem__\n    image = Image.open(img_loc).convert(\"RGB\")\n  File \"/home/vayzenbe/anaconda3/envs/ml_new/lib/python3.9/site-packages/PIL/Image.py\", line 3092, in open\n    fp = builtins.open(filename, \"rb\")\nIsADirectoryError: [Errno 21] Is a directory: '/lab_data/behrmannlab/image_sets/test_ims/train'\n"
     ]
    }
   ],
   "source": [
    "for data, ind,file in dataloader:\n",
    "    print(data.shape)\n",
    "    print(ind)\n",
    "    print(file)"
   ]
  },
  {
   "cell_type": "code",
   "execution_count": null,
   "metadata": {},
   "outputs": [],
   "source": []
  }
 ],
 "metadata": {
  "kernelspec": {
   "display_name": "Python 3 (ipykernel)",
   "language": "python",
   "name": "python3"
  },
  "language_info": {
   "codemirror_mode": {
    "name": "ipython",
    "version": 3
   },
   "file_extension": ".py",
   "mimetype": "text/x-python",
   "name": "python",
   "nbconvert_exporter": "python",
   "pygments_lexer": "ipython3",
   "version": "3.9.13"
  },
  "orig_nbformat": 4
 },
 "nbformat": 4,
 "nbformat_minor": 2
}
